<?xml version="1.0"?>
<robot name="niryo_ned" xmlns:xacro="http://www.ros.org/wiki/xacro">
  <xacro:property name="pi" value="3.14159265359"/>

  <!-- Base -->
  <link name="base_link">
    <visual>
      <origin xyz="0 0 0.05" rpy="0 0 0"/>
      <geometry>
        <cylinder length="0.1" radius="0.12"/>
      </geometry>
      <material name="blue">
        <color rgba="0.1 0.3 0.8 1.0"/>
      </material>
    </visual>
    <collision>
      <origin xyz="0 0 0.05" rpy="0 0 0"/>
      <geometry>
        <cylinder length="0.1" radius="0.12"/>
      </geometry>
    </collision>
  </link>

  <!-- Link 1 -->
  <link name="link_1">
    <visual>
      <origin xyz="0 0 0.07" rpy="0 0 0"/>
      <geometry>
        <cylinder length="0.14" radius="0.05"/>
      </geometry>
    </visual>
    <collision>
      <origin xyz="0 0 0.07" rpy="0 0 0"/>
      <geometry>
        <cylinder length="0.14" radius="0.05"/>
      </geometry>
    </collision>
  </link>
  <joint name="joint_1" type="revolute">
    <parent link="base_link"/>
    <child link="link_1"/>
    <origin xyz="0 0 0.09" rpy="0 0 0"/>
    <axis xyz="0 0 1"/>
    <limit lower="-3.14" upper="3.14" effort="50" velocity="1.0"/>
  </joint>

  <!-- Link 2 -->
  <link name="link_2">
    <visual>
      <origin xyz="0 0 0.10" rpy="0 0 0"/>
      <geometry>
        <cylinder length="0.20" radius="0.04"/>
      </geometry>
    </visual>
    <collision>
      <origin xyz="0 0 0.10" rpy="0 0 0"/>
      <geometry>
        <cylinder length="0.20" radius="0.04"/>
      </geometry>
    </collision>
  </link>
  <joint name="joint_2" type="revolute">
    <parent link="link_1"/>
    <child link="link_2"/>
    <origin xyz="0 0 0.14" rpy="0 0 0"/>
    <axis xyz="0 1 0"/>
    <limit lower="-3.14" upper="3.14" effort="50" velocity="1.0"/>
  </joint>

  <!-- Link 3 -->
  <link name="link_3">
    <visual>
      <origin xyz="0 0 0.10" rpy="0 0 0"/>
      <geometry>
        <cylinder length="0.20" radius="0.04"/>
      </geometry>
    </visual>
    <collision>
      <origin xyz="0 0 0.10" rpy="0 0 0"/>
      <geometry>
        <cylinder length="0.20" radius="0.04"/>
      </geometry>
    </collision>
  </link>
  <joint name="joint_3" type="revolute">
    <parent link="link_2"/>
    <child link="link_3"/>
    <origin xyz="0 0 0.20" rpy="0 0 0"/>
    <axis xyz="0 1 0"/>
    <limit lower="-3.14" upper="3.14" effort="50" velocity="1.0"/>
  </joint>

  <!-- Link 4 -->
  <link name="link_4">
    <visual>
      <origin xyz="0 0 0.08" rpy="0 0 0"/>
      <geometry>
        <cylinder length="0.16" radius="0.03"/>
      </geometry>
    </visual>
    <collision>
      <origin xyz="0 0 0.08" rpy="0 0 0"/>
      <geometry>
        <cylinder length="0.16" radius="0.03"/>
      </geometry>
    </collision>
  </link>
  <joint name="joint_4" type="revolute">
    <parent link="link_3"/>
    <child link="link_4"/>
    <origin xyz="0 0 0.20" rpy="0 0 0"/>
    <axis xyz="0 1 0"/>
    <limit lower="-3.14" upper="3.14" effort="50" velocity="1.0"/>
  </joint>

  <!-- Link 5 -->
  <link name="link_5">
    <visual>
      <origin xyz="0 0 0.06" rpy="0 0 0"/>
      <geometry>
        <cylinder length="0.12" radius="0.025"/>
      </geometry>
    </visual>
    <collision>
      <origin xyz="0 0 0.06" rpy="0 0 0"/>
      <geometry>
        <cylinder length="0.12" radius="0.025"/>
      </geometry>
    </collision>
  </link>
  <joint name="joint_5" type="revolute">
    <parent link="link_4"/>
    <child link="link_5"/>
    <origin xyz="0 0 0.16" rpy="0 0 0"/>
    <axis xyz="0 1 0"/>
    <limit lower="-3.14" upper="3.14" effort="50" velocity="1.0"/>
  </joint>

  <!-- Link 6 (end effector) -->
  <link name="link_6">
    <visual>
      <origin xyz="0 0 0.04" rpy="0 0 0"/>
      <geometry>
        <sphere radius="0.03"/>
      </geometry>
    </visual>
    <collision>
      <origin xyz="0 0 0.04" rpy="0 0 0"/>
      <geometry>
        <sphere radius="0.03"/>
      </geometry>
    </collision>
  </link>
  <joint name="joint_6" type="revolute">
    <parent link="link_5"/>
    <child link="link_6"/>
    <origin xyz="0 0 0.12" rpy="0 0 0"/>
    <axis xyz="0 1 0"/>
    <limit lower="-3.14" upper="3.14" effort="50" velocity="1.0"/>
  </joint>

</robot>